Workbook

Sheet Leia-me
A1: Argus — Catálogo de Dados
A2: Fonte única das séries de cada aba. Vira o arquivo de configuração do pipeline na Fase 1.
A5: Como usar
A6: Brasil / EUA | B6: Uma linha por indicador. Filtre por Aba, Fase ou Status. As colunas Fase e Status têm lista suspensa e podem ser editadas.
A7: Central | B7: Blocos da aba Central (Command Center) e do agregador de notícias.
A8: Fontes | B8: Registro de cada fonte: acesso, autenticação, limites e risco técnico.
A9: Resumo | B9: Contagens por aba, fase e status, calculadas por fórmula.
A11: Status
A12: Verificado | B12: Código conferido nesta sessão contra o portal oficial (título ou último valor).
A13: Confirmar | B13: Código conhecido, ainda não conferido. A validação automática da Fase 0 confirma título e última observação.
A14: A mapear | B14: Fonte definida, código ainda não localizado.
A15: Sem API | B15: Dado gratuito, mas só por download manual ou PDF. Entra como carga manual ou fica para v2.
A16: Pago | B16: Exige licença. A coluna Observação indica o substituto gratuito quando existe.
A17: Derivado | B17: Calculado pelo Argus a partir de outras séries. A fórmula está em Código / endpoint.
A18: Curado | B18: Tabela mantida manualmente (decisões do Copom, metas, pesquisas).
A20: Fase
A21: MVP | B21: Brasil + Central. Fontes oficiais com API, sem modelagem própria.
A22: EUA | B22: Logo após o MVP: mesmo template de abas, quase tudo via FRED.
A23: v2 | B23: Fontes difíceis (B3, ANBIMA, pesquisas, texto) ou modelos próprios.
A24: v3 | B24: Projetos de maior risco: NLP de discursos, fluxo B3, balanços CVM.
A26: Tipo | B26: Define quais transformações o motor de gráfico oferece. Ex.: taxa nunca vira acumulado 12m; variação mensal é encadeada, não somada.
A27: Data | B27: Planilha gerada a partir dos CSVs em docs/catalogo/. Edite os CSVs e rode o gerador; resultado da validação em validacao.md.

Sheet Resumo
A1: Resumo do catálogo
A2: Contagens calculadas a partir das abas Brasil e EUA.
A5: Brasil
A6: Aba | B6: MVP | C6: EUA | D6: v2 | E6: v3 | F6: Total | H6: Status | I6: Qtd
A7: Atividade | B7: =COUNTIFS(Brasil!$B$6:$B$146,$A7,Brasil!$K$6:$K$146,"MVP") | C7: =COUNTIFS(Brasil!$B$6:$B$146,$A7,Brasil!$K$6:$K$146,"EUA") | D7: =COUNTIFS(Brasil!$B$6:$B$146,$A7,Brasil!$K$6:$K$146,"v2") | E7: =COUNTIFS(Brasil!$B$6:$B$146,$A7,Brasil!$K$6:$K$146,"v3") | F7: =SUM(B7:E7) | H7: Verificado | I7: =COUNTIF(Brasil!$L$6:$L$146,H7)
A8: Mercado de Trabalho | B8: =COUNTIFS(Brasil!$B$6:$B$146,$A8,Brasil!$K$6:$K$146,"MVP") | C8: =COUNTIFS(Brasil!$B$6:$B$146,$A8,Brasil!$K$6:$K$146,"EUA") | D8: =COUNTIFS(Brasil!$B$6:$B$146,$A8,Brasil!$K$6:$K$146,"v2") | E8: =COUNTIFS(Brasil!$B$6:$B$146,$A8,Brasil!$K$6:$K$146,"v3") | F8: =SUM(B8:E8) | H8: Confirmar | I8: =COUNTIF(Brasil!$L$6:$L$146,H8)
A9: Inflação | B9: =COUNTIFS(Brasil!$B$6:$B$146,$A9,Brasil!$K$6:$K$146,"MVP") | C9: =COUNTIFS(Brasil!$B$6:$B$146,$A9,Brasil!$K$6:$K$146,"EUA") | D9: =COUNTIFS(Brasil!$B$6:$B$146,$A9,Brasil!$K$6:$K$146,"v2") | E9: =COUNTIFS(Brasil!$B$6:$B$146,$A9,Brasil!$K$6:$K$146,"v3") | F9: =SUM(B9:E9) | H9: A mapear | I9: =COUNTIF(Brasil!$L$6:$L$146,H9)
A10: Política Monetária | B10: =COUNTIFS(Brasil!$B$6:$B$146,$A10,Brasil!$K$6:$K$146,"MVP") | C10: =COUNTIFS(Brasil!$B$6:$B$146,$A10,Brasil!$K$6:$K$146,"EUA") | D10: =COUNTIFS(Brasil!$B$6:$B$146,$A10,Brasil!$K$6:$K$146,"v2") | E10: =COUNTIFS(Brasil!$B$6:$B$146,$A10,Brasil!$K$6:$K$146,"v3") | F10: =SUM(B10:E10) | H10: Sem API | I10: =COUNTIF(Brasil!$L$6:$L$146,H10)
A11: Fiscal | B11: =COUNTIFS(Brasil!$B$6:$B$146,$A11,Brasil!$K$6:$K$146,"MVP") | C11: =COUNTIFS(Brasil!$B$6:$B$146,$A11,Brasil!$K$6:$K$146,"EUA") | D11: =COUNTIFS(Brasil!$B$6:$B$146,$A11,Brasil!$K$6:$K$146,"v2") | E11: =COUNTIFS(Brasil!$B$6:$B$146,$A11,Brasil!$K$6:$K$146,"v3") | F11: =SUM(B11:E11) | H11: Pago | I11: =COUNTIF(Brasil!$L$6:$L$146,H11)
A12: Setor Externo | B12: =COUNTIFS(Brasil!$B$6:$B$146,$A12,Brasil!$K$6:$K$146,"MVP") | C12: =COUNTIFS(Brasil!$B$6:$B$146,$A12,Brasil!$K$6:$K$146,"EUA") | D12: =COUNTIFS(Brasil!$B$6:$B$146,$A12,Brasil!$K$6:$K$146,"v2") | E12: =COUNTIFS(Brasil!$B$6:$B$146,$A12,Brasil!$K$6:$K$146,"v3") | F12: =SUM(B12:E12) | H12: Derivado | I12: =COUNTIF(Brasil!$L$6:$L$146,H12)
A13: Famílias | B13: =COUNTIFS(Brasil!$B$6:$B$146,$A13,Brasil!$K$6:$K$146,"MVP") | C13: =COUNTIFS(Brasil!$B$6:$B$146,$A13,Brasil!$K$6:$K$146,"EUA") | D13: =COUNTIFS(Brasil!$B$6:$B$146,$A13,Brasil!$K$6:$K$146,"v2") | E13: =COUNTIFS(Brasil!$B$6:$B$146,$A13,Brasil!$K$6:$K$146,"v3") | F13: =SUM(B13:E13) | H13: Curado | I13: =COUNTIF(Brasil!$L$6:$L$146,H13)
A14: Empresas | B14: =COUNTIFS(Brasil!$B$6:$B$146,$A14,Brasil!$K$6:$K$146,"MVP") | C14: =COUNTIFS(Brasil!$B$6:$B$146,$A14,Brasil!$K$6:$K$146,"EUA") | D14: =COUNTIFS(Brasil!$B$6:$B$146,$A14,Brasil!$K$6:$K$146,"v2") | E14: =COUNTIFS(Brasil!$B$6:$B$146,$A14,Brasil!$K$6:$K$146,"v3") | F14: =SUM(B14:E14)
A15: Mercado & Risco | B15: =COUNTIFS(Brasil!$B$6:$B$146,$A15,Brasil!$K$6:$K$146,"MVP") | C15: =COUNTIFS(Brasil!$B$6:$B$146,$A15,Brasil!$K$6:$K$146,"EUA") | D15: =COUNTIFS(Brasil!$B$6:$B$146,$A15,Brasil!$K$6:$K$146,"v2") | E15: =COUNTIFS(Brasil!$B$6:$B$146,$A15,Brasil!$K$6:$K$146,"v3") | F15: =SUM(B15:E15)
A16: Política | B16: =COUNTIFS(Brasil!$B$6:$B$146,$A16,Brasil!$K$6:$K$146,"MVP") | C16: =COUNTIFS(Brasil!$B$6:$B$146,$A16,Brasil!$K$6:$K$146,"EUA") | D16: =COUNTIFS(Brasil!$B$6:$B$146,$A16,Brasil!$K$6:$K$146,"v2") | E16: =COUNTIFS(Brasil!$B$6:$B$146,$A16,Brasil!$K$6:$K$146,"v3") | F16: =SUM(B16:E16)
A17: Análises | B17: =COUNTIFS(Brasil!$B$6:$B$146,$A17,Brasil!$K$6:$K$146,"MVP") | C17: =COUNTIFS(Brasil!$B$6:$B$146,$A17,Brasil!$K$6:$K$146,"EUA") | D17: =COUNTIFS(Brasil!$B$6:$B$146,$A17,Brasil!$K$6:$K$146,"v2") | E17: =COUNTIFS(Brasil!$B$6:$B$146,$A17,Brasil!$K$6:$K$146,"v3") | F17: =SUM(B17:E17)
A18: Central | B18: =COUNTIFS(Brasil!$B$6:$B$146,$A18,Brasil!$K$6:$K$146,"MVP") | C18: =COUNTIFS(Brasil!$B$6:$B$146,$A18,Brasil!$K$6:$K$146,"EUA") | D18: =COUNTIFS(Brasil!$B$6:$B$146,$A18,Brasil!$K$6:$K$146,"v2") | E18: =COUNTIFS(Brasil!$B$6:$B$146,$A18,Brasil!$K$6:$K$146,"v3") | F18: =SUM(B18:E18)
A19: Total | B19: =SUM(B7:B18) | C19: =SUM(C7:C18) | D19: =SUM(D7:D18) | E19: =SUM(E7:E18) | F19: =SUM(F7:F18)
A21: EUA
A22: Aba | B22: MVP | C22: EUA | D22: v2 | E22: v3 | F22: Total | H22: Status | I22: Qtd
A23: Mercado de Trabalho | B23: =COUNTIFS(EUA!$B$6:$B$101,$A23,EUA!$K$6:$K$101,"MVP") | C23: =COUNTIFS(EUA!$B$6:$B$101,$A23,EUA!$K$6:$K$101,"EUA") | D23: =COUNTIFS(EUA!$B$6:$B$101,$A23,EUA!$K$6:$K$101,"v2") | E23: =COUNTIFS(EUA!$B$6:$B$101,$A23,EUA!$K$6:$K$101,"v3") | F23: =SUM(B23:E23) | H23: Verificado | I23: =COUNTIF(EUA!$L$6:$L$101,H23)
A24: Inflação | B24: =COUNTIFS(EUA!$B$6:$B$101,$A24,EUA!$K$6:$K$101,"MVP") | C24: =COUNTIFS(EUA!$B$6:$B$101,$A24,EUA!$K$6:$K$101,"EUA") | D24: =COUNTIFS(EUA!$B$6:$B$101,$A24,EUA!$K$6:$K$101,"v2") | E24: =COUNTIFS(EUA!$B$6:$B$101,$A24,EUA!$K$6:$K$101,"v3") | F24: =SUM(B24:E24) | H24: Confirmar | I24: =COUNTIF(EUA!$L$6:$L$101,H24)
A25: Atividade | B25: =COUNTIFS(EUA!$B$6:$B$101,$A25,EUA!$K$6:$K$101,"MVP") | C25: =COUNTIFS(EUA!$B$6:$B$101,$A25,EUA!$K$6:$K$101,"EUA") | D25: =COUNTIFS(EUA!$B$6:$B$101,$A25,EUA!$K$6:$K$101,"v2") | E25: =COUNTIFS(EUA!$B$6:$B$101,$A25,EUA!$K$6:$K$101,"v3") | F25: =SUM(B25:E25) | H25: A mapear | I25: =COUNTIF(EUA!$L$6:$L$101,H25)
A26: Fed & Juros | B26: =COUNTIFS(EUA!$B$6:$B$101,$A26,EUA!$K$6:$K$101,"MVP") | C26: =COUNTIFS(EUA!$B$6:$B$101,$A26,EUA!$K$6:$K$101,"EUA") | D26: =COUNTIFS(EUA!$B$6:$B$101,$A26,EUA!$K$6:$K$101,"v2") | E26: =COUNTIFS(EUA!$B$6:$B$101,$A26,EUA!$K$6:$K$101,"v3") | F26: =SUM(B26:E26) | H26: Sem API | I26: =COUNTIF(EUA!$L$6:$L$101,H26)
A27: Imobiliário | B27: =COUNTIFS(EUA!$B$6:$B$101,$A27,EUA!$K$6:$K$101,"MVP") | C27: =COUNTIFS(EUA!$B$6:$B$101,$A27,EUA!$K$6:$K$101,"EUA") | D27: =COUNTIFS(EUA!$B$6:$B$101,$A27,EUA!$K$6:$K$101,"v2") | E27: =COUNTIFS(EUA!$B$6:$B$101,$A27,EUA!$K$6:$K$101,"v3") | F27: =SUM(B27:E27) | H27: Pago | I27: =COUNTIF(EUA!$L$6:$L$101,H27)
A28: Consumidor | B28: =COUNTIFS(EUA!$B$6:$B$101,$A28,EUA!$K$6:$K$101,"MVP") | C28: =COUNTIFS(EUA!$B$6:$B$101,$A28,EUA!$K$6:$K$101,"EUA") | D28: =COUNTIFS(EUA!$B$6:$B$101,$A28,EUA!$K$6:$K$101,"v2") | E28: =COUNTIFS(EUA!$B$6:$B$101,$A28,EUA!$K$6:$K$101,"v3") | F28: =SUM(B28:E28) | H28: Derivado | I28: =COUNTIF(EUA!$L$6:$L$101,H28)
A29: Corporativo | B29: =COUNTIFS(EUA!$B$6:$B$101,$A29,EUA!$K$6:$K$101,"MVP") | C29: =COUNTIFS(EUA!$B$6:$B$101,$A29,EUA!$K$6:$K$101,"EUA") | D29: =COUNTIFS(EUA!$B$6:$B$101,$A29,EUA!$K$6:$K$101,"v2") | E29: =COUNTIFS(EUA!$B$6:$B$101,$A29,EUA!$K$6:$K$101,"v3") | F29: =SUM(B29:E29) | H29: Curado | I29: =COUNTIF(EUA!$L$6:$L$101,H29)
A30: Setor Externo & Fiscal | B30: =COUNTIFS(EUA!$B$6:$B$101,$A30,EUA!$K$6:$K$101,"MVP") | C30: =COUNTIFS(EUA!$B$6:$B$101,$A30,EUA!$K$6:$K$101,"EUA") | D30: =COUNTIFS(EUA!$B$6:$B$101,$A30,EUA!$K$6:$K$101,"v2") | E30: =COUNTIFS(EUA!$B$6:$B$101,$A30,EUA!$K$6:$K$101,"v3") | F30: =SUM(B30:E30)
A31: Risco & Mercado | B31: =COUNTIFS(EUA!$B$6:$B$101,$A31,EUA!$K$6:$K$101,"MVP") | C31: =COUNTIFS(EUA!$B$6:$B$101,$A31,EUA!$K$6:$K$101,"EUA") | D31: =COUNTIFS(EUA!$B$6:$B$101,$A31,EUA!$K$6:$K$101,"v2") | E31: =COUNTIFS(EUA!$B$6:$B$101,$A31,EUA!$K$6:$K$101,"v3") | F31: =SUM(B31:E31)
A32: Total | B32: =SUM(B23:B31) | C32: =SUM(C23:C31) | D32: =SUM(D23:D31) | E32: =SUM(E23:E31) | F32: =SUM(F23:F31)

Sheet Brasil
A1: Brasil — catálogo de séries
A2: Subabas da aba Brasil. Foco do MVP.
A5: ID | B5: Aba | C5: Bloco | D5: Indicador | E5: Fonte | F5: Código / endpoint | G5: Frequência | H5: Unidade | I5: Tipo | J5: Transformações válidas | K5: Fase | L5: Status | M5: Observação
A6: BR-001 | B6: Atividade | C6: PIB | D6: PIB real — índice de volume (SA) | E6: IBGE SIDRA | F6: t1621/v584/c11255=90707 | G6: Trimestral | H6: Índice | I6: Índice | J6: Nível, MoM, QoQ, YoY, acum. 3/6/9/12m, 3m/6m SAAR, real/nominal | K6: MVP | L6: Verificado | M6: Série encadeada com ajuste sazonal; base para QoQ SAAR
A7: BR-002 | B7: Atividade | C7: PIB | D7: PIB real — taxas (QoQ, YoY, acum. 4T) | E7: IBGE SIDRA | F7: t5932/v6561,6562,6564/c11255=90707 | G7: Trimestral | H7: % | I7: Taxa | J7: Nível, Δ p.p. (MoM, YoY, 3/6/12m) | K7: MVP | L7: Verificado | M7: Taxas oficiais; usar para conferir cálculo próprio
A8: BR-003 | B8: Atividade | C8: PIB | D8: PIB — ótica da oferta (agro, indústria, serviços) | E8: IBGE SIDRA | F8: t1621/v584/c11255=90687,90691,90696 | G8: Trimestral | H8: Índice | I8: Índice | J8: Nível, MoM, QoQ, YoY, acum. 3/6/9/12m, 3m/6m SAAR, real/nominal | K8: MVP | L8: Verificado
A9: BR-004 | B9: Atividade | C9: PIB | D9: PIB — ótica da demanda (C, G, FBCF, X, M) | E9: IBGE SIDRA | F9: t1621/v584/c11255=93404,93405,93406,93407,93408 | G9: Trimestral | H9: Índice | I9: Índice | J9: Nível, MoM, QoQ, YoY, acum. 3/6/9/12m, 3m/6m SAAR, real/nominal | K9: MVP | L9: Verificado | M9: Consumo das famílias também alimenta a aba Famílias
A10: BR-005 | B10: Atividade | C10: PIB | D10: PIB nominal acumulado 12m (R$) | E10: BCB SGS | F10: 4382 | G10: Mensal | H10: R$ mi | I10: Fluxo | J10: Nível, soma 3/12m, MoM % (SA), YoY %, real/nominal, % PIB | K10: MVP | L10: Verificado | M10: Denominador de todas as razões % PIB
A11: BR-006 | B11: Atividade | C11: Mensais | D11: IBC-Br (SA) | E11: BCB SGS | F11: 24364 | G11: Mensal | H11: Índice | I11: Índice | J11: Nível, MoM, QoQ, YoY, acum. 3/6/9/12m, 3m/6m SAAR, real/nominal | K11: MVP | L11: Verificado | M11: Sem ajuste: 24363
A12: BR-007 | B12: Atividade | C12: Mensais | D12: Produção industrial — PIM-PF (geral, extrativa, transformação) | E12: IBGE SIDRA | F12: t8888/v12606,12607/c544=129314,129315,129316 ; t8888/v11602,11604/c544=129314 | G12: Mensal | H12: Índice | I12: Índice | J12: Nível, MoM, QoQ, YoY, acum. 3/6/9/12m, 3m/6m SAAR, real/nominal | K12: MVP | L12: Verificado | M12: Tabela nova (base 2022); conferir na Fase 0; v11602 (YoY) e v11604 (12 meses) são as taxas oficiais, usadas para conferir o cálculo do site
A13: BR-008 | B13: Atividade | C13: Mensais | D13: Varejo restrito e ampliado — PMC | E13: IBGE SIDRA | F13: t8880/v7169,7170/c11046=56733,56734 ; t8881/v7169,7170/c11046=56735,56736 ; t8880/v11708/c11046=56734 | G13: Mensal | H13: Índice | I13: Índice | J13: Nível, MoM, QoQ, YoY, acum. 3/6/9/12m, 3m/6m SAAR, real/nominal | K13: MVP | L13: Verificado | M13: Volume e receita nominal; t8880 v11708 (MoM SA oficial) confere o cálculo do site
A14: BR-009 | B14: Atividade | C14: Mensais | D14: Volume de serviços — PMS | E14: IBGE SIDRA | F14: t5906/v7167,7168/c11046=56725,56726 | G14: Mensal | H14: Índice | I14: Índice | J14: Nível, MoM, QoQ, YoY, acum. 3/6/9/12m, 3m/6m SAAR, real/nominal | K14: MVP | L14: Verificado
A15: BR-010 | B15: Atividade | C15: Mensais | D15: Utilização da capacidade instalada (NUCI) | E15: FGV IBRE / CNI | F15: — | G15: Mensal | H15: % | I15: Taxa | J15: Nível, Δ p.p. (MoM, YoY, 3/6/12m) | K15: v2 | L15: Sem API | M15: FGV restringe dados; CNI publica xlsx
A16: BR-011 | B16: Atividade | C16: Confiança | D16: Confiança FGV (consumidor, indústria, serviços, comércio) | E16: FGV IBRE | F16: — | G16: Mensal | H16: Índice | I16: Índice | J16: Nível, MoM, QoQ, YoY, acum. 3/6/9/12m, 3m/6m SAAR, real/nominal | K16: v2 | L16: Sem API | M16: Sem API aberta; download manual ou assinatura
A17: BR-012 | B17: Atividade | C17: Coincidentes | D17: Produção de veículos (Anfavea) | E17: Anfavea | F17: — | G17: Mensal | H17: Unidades | I17: Fluxo | J17: Nível, soma 3/12m, MoM % (SA), YoY %, real/nominal, % PIB | K17: v2 | L17: Sem API | M17: xlsx no site
A18: BR-013 | B18: Atividade | C18: Coincidentes | D18: Carga de energia (ONS) | E18: ONS Dados Abertos | F18: — | G18: Diária | H18: MWmed | I18: Fluxo | J18: Nível, soma 3/12m, MoM % (SA), YoY %, real/nominal, % PIB | K18: v2 | L18: A mapear | M18: Proxy de atividade de alta frequência
A19: BR-014 | B19: Atividade | C19: Expectativas | D19: Focus — PIB (ano corrente e seguinte) | E19: BCB Olinda (Focus) | F19: ExpectativasMercadoAnuais · Indicador='PIB Total' | G19: Semanal | H19: % | I19: Taxa | J19: Nível, Δ p.p. (MoM, YoY, 3/6/12m) | K19: MVP | L19: Verificado | M19: Mediana, desvio e nº de respondentes
A20: BR-015 | B20: Mercado de Trabalho | C20: PNAD | D20: Taxa de desocupação | E20: BCB SGS / IBGE SIDRA | F20: 24369 / t6381 | G20: Mensal (trim. móvel) | H20: % | I20: Taxa | J20: Nível, Δ p.p. (MoM, YoY, 3/6/12m) | K20: MVP | L20: Verificado | M20: Série oficial sem ajuste sazonal; SA própria (X-13) na v2
A21: BR-016 | B21: Mercado de Trabalho | C21: PNAD | D21: Taxa de participação e nível de ocupação | E21: IBGE SIDRA | F21: t5944/v4096 ; t6379/v4097 | G21: Mensal (trim. móvel) | H21: % | I21: Taxa | J21: Nível, Δ p.p. (MoM, YoY, 3/6/12m) | K21: MVP | L21: Verificado | M21: PNAD Contínua mensal: t5944 participação, t6379 nível da ocupação
A22: BR-017 | B22: Mercado de Trabalho | C22: PNAD | D22: População ocupada (total, formal, informal) | E22: IBGE SIDRA | F22: t8501/v4090/c1350=57302,57303 | G22: Mensal (trim. móvel) | H22: Mil pessoas | I22: Estoque | J22: Nível, MoM %, YoY %, real/nominal, % PIB | K22: MVP | L22: Verificado | M22: PNAD Contínua mensal, por situação de informalidade
A23: BR-018 | B23: Mercado de Trabalho | C23: PNAD | D23: Taxa de informalidade | E23: IBGE SIDRA | F23: t8513/v12466 | G23: Mensal (trim. móvel) | H23: % | I23: Taxa | J23: Nível, Δ p.p. (MoM, YoY, 3/6/12m) | K23: MVP | L23: Verificado | M23: PNAD Contínua mensal
A24: BR-019 | B24: Mercado de Trabalho | C24: PNAD | D24: Rendimento médio real habitual | E24: IBGE SIDRA | F24: t6390/v5933,5929 | G24: Mensal (trim. móvel) | H24: R$ | I24: Índice | J24: Nível, MoM, QoQ, YoY, acum. 3/6/9/12m, 3m/6m SAAR, real/nominal | K24: MVP | L24: Verificado | M24: Equivalente a AHE/real wage dos EUA
A25: BR-020 | B25: Mercado de Trabalho | C25: PNAD | D25: Massa de rendimento real habitual | E25: IBGE SIDRA | F25: t6392/v6293,6288 | G25: Mensal (trim. móvel) | H25: R$ mi | I25: Fluxo | J25: Nível, soma 3/12m, MoM % (SA), YoY %, real/nominal, % PIB | K25: MVP | L25: Verificado | M25: PNAD Contínua mensal, habitualmente recebido; liga Trabalho a Consumo
A26: BR-021 | B26: Mercado de Trabalho | C26: PNAD | D26: Subutilização, desalentados, desemprego de longo prazo | E26: IBGE SIDRA | F26: PNAD Contínua trimestral | G26: Trimestral | H26: % | I26: Taxa | J26: Nível, Δ p.p. (MoM, YoY, 3/6/12m) | K26: v2 | L26: A mapear | M26: Equivalente ao U6 dos EUA
... A32: BR-027 | B32: Inflação | C32: Cheio | D32: IPCA-15 | E32: BCB SGS | F32: 7478 | G32: Mensal | H32: % m/m | I32: Var % mensal | J32: Mensal, acum. 3/6/9/12m (encadeado), 3m/6m anualizado, YoY via 12m | K32: MVP | L32: Verificado | M32: Prévia
A33: BR-028 | B33: Inflação | C33: Cheio | D33: INPC | E33: BCB SGS | F33: 188 | G33: Mensal | H33: % m/m | I33: Var % mensal | J33: Mensal, acum. 3/6/9/12m (encadeado), 3m/6m anualizado, YoY via 12m | K33: v2 | L33: Confirmar
A34: BR-029 | B34: Inflação | C34: Núcleos | D34: Núcleo médias aparadas sem suavização (MA) | E34: BCB SGS | F34: 11426 | G34: Mensal | H34: % m/m | I34: Var % mensal | J34: Mensal, acum. 3/6/9/12m (encadeado), 3m/6m anualizado, YoY via 12m | K34: MVP | L34: Verificado
A35: BR-030 | B35: Inflação | C35: Núcleos | D35: Núcleo médias aparadas com suavização (MS) | E35: BCB SGS | F35: 4466 | G35: Mensal | H35: % m/m | I35: Var % mensal | J35: Mensal, acum. 3/6/9/12m (encadeado), 3m/6m anualizado, YoY via 12m | K35: MVP | L35: Verificado
A36: BR-031 | B36: Inflação | C36: Núcleos | D36: Núcleo por exclusão EX0 (sem monitorados e alim. domicílio) | E36: BCB SGS | F36: 11427 | G36: Mensal | H36: % m/m | I36: Var % mensal | J36: Mensal, acum. 3/6/9/12m (encadeado), 3m/6m anualizado, YoY via 12m | K36: MVP | L36: Verificado
A37: BR-032 | B37: Inflação | C37: Núcleos | D37: Núcleo por exclusão EX2 | E37: BCB SGS | F37: 27838 | G37: Mensal | H37: % m/m | I37: Var % mensal | J37: Mensal, acum. 3/6/9/12m (encadeado), 3m/6m anualizado, YoY via 12m | K37: MVP | L37: Verificado | M37: NT 57 (dez/2025, Tabela 11): EX1 = 16121 e EX2 = 27838; o título SGS de 16121 ('ex2') é enganoso; validador 2026-10-04: título oficial confere
A38: BR-033 | B38: Inflação | C38: Núcleos | D38: Núcleo de dupla ponderação (DP) | E38: BCB SGS | F38: 16122 | G38: Mensal | H38: % m/m | I38: Var % mensal | J38: Mensal, acum. 3/6/9/12m (encadeado), 3m/6m anualizado, YoY via 12m | K38: MVP | L38: Verificado
A39: BR-034 | B39: Inflação | C39: Núcleos | D39: Núcleos EX3 e P55 | E39: BCB SGS | F39: 27839 / 28750 | G39: Mensal | H39: % m/m | I39: Var % mensal | J39: Mensal, acum. 3/6/9/12m (encadeado), 3m/6m anualizado, YoY via 12m | K39: MVP | L39: Verificado | M39: Títulos SGS: "Núcleo por exclusão - EX3" (27839) e "Núcleo Percentil 55" (28750); sondagem 2026-10-04
A40: BR-126 | B40: Inflação | C40: Núcleos | D40: Núcleo ex-alimentação e energia (EX-FE) | E40: BCB SGS | F40: 28751 | G40: Mensal | H40: % m/m | I40: Var % mensal | J40: Mensal, acum. 3/6/9/12m (encadeado), 3m/6m anualizado, YoY via 12m | K40: MVP | L40: Verificado | M40: Título SGS 28751: "Núcleo Ex-alimentação e energia (EX-FE)"; comparável ao core dos EUA
A41: BR-127 | B41: Inflação | C41: Núcleos | D41: Média dos 5 núcleos do Copom (EX0, EX3, MS, DP, P55) | E41: Argus | F41: média(11427, 27839, 4466, 16122, 28750) | G41: Mensal | H41: % m/m | I41: Derivado | J41: Mensal, acum. 3/6/9/12m (encadeado), 3m/6m anualizado, YoY via 12m | K41: MVP | L41: Derivado | M41: Leitura-síntese citada pelo Copom; recalcular e conferir contra o RPM
A42: BR-128 | B42: Inflação | C42: Núcleos | D42: Mediana ponderada do IPCA (P50) | E42: Argus | F42: f(t7060): subitens ordenados por variação, peso acumulado = 50% | G42: Mensal | H42: % m/m | I42: Derivado | J42: Mensal, acum. 3/6/9/12m (encadeado), 3m/6m anualizado, YoY via 12m | K42: MVP | L42: Derivado | M42: Método do P55 do BCB (NT 57) em 50%; o mesmo cálculo em 55% reproduz o SGS 28750 em 80 de 80 meses (2020-2026). Desde 2020 (tabela 7060)
A43: BR-129 | B43: Inflação | C43: Núcleos | D43: Bens industriais subjacentes (EX3 Industriais) | E43: BCB SGS | F43: 29684 | G43: Mensal | H43: % m/m | I43: Var % mensal | J43: Mensal, acum. 3/6/9/12m (encadeado), 3m/6m anualizado, YoY via 12m | K43: MVP | L43: Verificado | M43: Série oficial do BCB desde a NT 57 (dez/2025, Tabela 11): antes era cálculo próprio; validador 2026-10-04: título oficial confere
A44: BR-130 | B44: Inflação | C44: Núcleos | D44: Serviços intensivos em trabalho | E44: Argus | F44: f(t7060): subitens de serviços com alto peso de mão de obra | G44: Mensal | H44: % m/m | I44: Derivado | J44: Mensal, acum. 3/6/9/12m (encadeado), 3m/6m anualizado, YoY via 12m | K44: MVP | L44: Derivado | M44: Lista de subitens curada a partir da classificação do BCB; ligação com Mercado de Trabalho
A45: BR-131 | B45: Inflação | C45: Núcleos | D45: Preços rígidos × flexíveis (sticky/flexible) | E45: Argus | F45: f(t7060 + classificação por frequência de reajuste) | G45: Mensal | H45: % m/m | I45: Derivado | J45: Mensal, acum. 3/6/9/12m (encadeado), 3m/6m anualizado, YoY via 12m | K45: v2 | L45: Derivado | M45: Estilo Fed de Atlanta; exige montar a classificação de subitens
A46: BR-035 | B46: Inflação | C46: Aberturas | D46: Preços livres | E46: BCB SGS | F46: 11428 | G46: Mensal | H46: % m/m | I46: Var % mensal | J46: Mensal, acum. 3/6/9/12m (encadeado), 3m/6m anualizado, YoY via 12m | K46: MVP | L46: Verificado
A47: BR-036 | B47: Inflação | C47: Aberturas | D47: Preços monitorados | E47: BCB SGS | F47: 4449 | G47: Mensal | H47: % m/m | I47: Var % mensal | J47: Mensal, acum. 3/6/9/12m (encadeado), 3m/6m anualizado, YoY via 12m | K47: MVP | L47: Verificado
...

Sheet EUA
A1: EUA — catálogo de séries
A2: Mapeamento da planilha original de dados US para fonte e código.
A5: ID | B5: Aba | C5: Bloco | D5: Indicador | E5: Fonte | F5: Código / endpoint | G5: Frequência | H5: Unidade | I5: Tipo | J5: Transformações válidas | K5: Fase | L5: Status | M5: Observação
A6: US-001 | B6: Mercado de Trabalho | C6: Payroll | D6: Non-farm Payrolls | E6: FRED (BLS) | F6: PAYEMS | G6: Mensal | H6: Mil | I6: Estoque | J6: Nível, MoM %, YoY %, real/nominal, % PIB | K6: EUA | L6: Verificado
A7: US-002 | B7: Mercado de Trabalho | C7: Desemprego | D7: Unemployment Rate (U3) | E7: FRED (BLS) | F7: UNRATE | G7: Mensal | H7: % | I7: Taxa | J7: Nível, Δ p.p. (MoM, YoY, 3/6/12m) | K7: EUA | L7: Verificado
A8: US-003 | B8: Mercado de Trabalho | C8: Desemprego | D8: Unemployment Breakdown (U6, demografia) | E8: FRED (BLS) | F8: U6RATE + séries LNS140000xx | G8: Mensal | H8: % | I8: Taxa | J8: Nível, Δ p.p. (MoM, YoY, 3/6/12m) | K8: EUA | L8: Verificado
A9: US-004 | B9: Mercado de Trabalho | C9: Participação | D9: Labour Force Participation (total e 25–54) | E9: FRED (BLS) | F9: CIVPART / LNS11300060 | G9: Mensal | H9: % | I9: Taxa | J9: Nível, Δ p.p. (MoM, YoY, 3/6/12m) | K9: EUA | L9: Verificado
A10: US-005 | B10: Mercado de Trabalho | C10: JOLTS | D10: Job Openings to Unemployed Ratio | E10: Argus | F10: JTSJOL / UNEMPLOY | G10: Mensal | H10: x | I10: Derivado | J10: Conforme definição da fórmula | K10: EUA | L10: Derivado
A11: US-006 | B11: Mercado de Trabalho | C11: JOLTS | D11: JOLTS Openings, Hires, Quits, Layoffs | E11: FRED (BLS) | F11: JTSJOL / JTSHIL / JTSQUL / JTSLDL | G11: Mensal | H11: Mil | I11: Fluxo | J11: Nível, soma 3/12m, MoM % (SA), YoY %, real/nominal, % PIB | K11: EUA | L11: Verificado
A12: US-007 | B12: Mercado de Trabalho | C12: Claims | D12: Jobless Claims (Initial & Continuing) | E12: FRED (DOL) | F12: ICSA / CCSA | G12: Semanal | H12: Mil | I12: Fluxo | J12: Nível, soma 3/12m, MoM % (SA), YoY %, real/nominal, % PIB | K12: EUA | L12: Verificado
A13: US-008 | B13: Mercado de Trabalho | C13: Pesquisas | D13: Jobs Hard to Find (Conference Board) | E13: Conference Board | F13: — | G13: Mensal | H13: % | I13: Taxa | J13: Nível, Δ p.p. (MoM, YoY, 3/6/12m) | K13: v2 | L13: Pago | M13: Proxy gratuita: nenhuma equivalente direta
A14: US-009 | B14: Mercado de Trabalho | C14: Pesquisas | D14: NFIB Job Openings Hard to Fill / Hiring Plans | E14: NFIB | F14: Relatório mensal (PDF) | G14: Mensal | H14: % | I14: Taxa | J14: Nível, Δ p.p. (MoM, YoY, 3/6/12m) | K14: v2 | L14: Sem API
A15: US-010 | B15: Mercado de Trabalho | C15: Indicadores | D15: Beveridge Curve | E15: Argus | F15: UNRATE × JTSJOR | G15: Mensal | H15: % | I15: Derivado | J15: Conforme definição da fórmula | K15: EUA | L15: Derivado
A16: US-011 | B16: Mercado de Trabalho | C16: Salários | D16: Employment Cost Index | E16: FRED (BLS) | F16: ECIALLCIV | G16: Trimestral | H16: Índice | I16: Índice | J16: Nível, MoM, QoQ, YoY, acum. 3/6/9/12m, 3m/6m SAAR, real/nominal | K16: EUA | L16: Verificado
A17: US-012 | B17: Mercado de Trabalho | C17: Salários | D17: Average Hourly Earnings | E17: FRED (BLS) | F17: CES0500000003 | G17: Mensal | H17: US$ | I17: Índice | J17: Nível, MoM, QoQ, YoY, acum. 3/6/9/12m, 3m/6m SAAR, real/nominal | K17: EUA | L17: Verificado
A18: US-013 | B18: Mercado de Trabalho | C18: Salários | D18: Real Wage Growth | E18: Argus | F18: f(CES0500000003, CPIAUCSL) | G18: Mensal | H18: % | I18: Derivado | J18: Conforme definição da fórmula | K18: EUA | L18: Derivado
A19: US-014 | B19: Mercado de Trabalho | C19: Salários | D19: Wage Growth Tracker (job switcher) | E19: Atlanta Fed | F19: Download (xlsx) | G19: Mensal | H19: % | I19: Taxa | J19: Nível, Δ p.p. (MoM, YoY, 3/6/12m) | K19: v2 | L19: Sem API | M19: Não encontrado no FRED com o código testado
A20: US-015 | B20: Mercado de Trabalho | C20: Indicadores | D20: Sahm Rule (real-time) | E20: FRED | F20: SAHMREALTIME | G20: Mensal | H20: p.p. | I20: Taxa | J20: Nível, Δ p.p. (MoM, YoY, 3/6/12m) | K20: EUA | L20: Verificado | M20: 0,00 p.p. em 09/2026
A21: US-016 | B21: Inflação | C21: CPI | D21: CPI Headline e Core | E21: FRED (BLS) | F21: CPIAUCSL / CPILFESL | G21: Mensal | H21: Índice | I21: Índice | J21: Nível, MoM, QoQ, YoY, acum. 3/6/9/12m, 3m/6m SAAR, real/nominal | K21: EUA | L21: Verificado
A22: US-017 | B22: Inflação | C22: CPI | D22: Supercore (services less rent of shelter) | E22: FRED (BLS) | F22: CUSR0000SASL2RS | G22: Mensal | H22: Índice | I22: Índice | J22: Nível, MoM, QoQ, YoY, acum. 3/6/9/12m, 3m/6m SAAR, real/nominal | K22: EUA | L22: Verificado | M22: Proxy; supercore estrito exclui também energia
A23: US-018 | B23: Inflação | C23: CPI | D23: Rent CPI e Owner Equivalent Rent | E23: FRED (BLS) | F23: CUSR0000SEHA / CUSR0000SEHC | G23: Mensal | H23: Índice | I23: Índice | J23: Nível, MoM, QoQ, YoY, acum. 3/6/9/12m, 3m/6m SAAR, real/nominal | K23: EUA | L23: Verificado
A24: US-019 | B24: Inflação | C24: PCE | D24: PCE e Core PCE | E24: FRED (BEA) | F24: PCEPI / PCEPILFE | G24: Mensal | H24: Índice | I24: Índice | J24: Nível, MoM, QoQ, YoY, acum. 3/6/9/12m, 3m/6m SAAR, real/nominal | K24: EUA | L24: Verificado
A25: US-020 | B25: Inflação | C25: PCE | D25: Trimmed Mean PCE (Dallas Fed, 12m) | E25: FRED | F25: PCETRIM12M159SFRBDAL | G25: Mensal | H25: % | I25: Taxa | J25: Nível, Δ p.p. (MoM, YoY, 3/6/12m) | K25: EUA | L25: Verificado
A26: US-021 | B26: Inflação | C26: PPI | D26: PPI Final Demand | E26: FRED (BLS) | F26: PPIFIS | G26: Mensal | H26: Índice | I26: Índice | J26: Nível, MoM, QoQ, YoY, acum. 3/6/9/12m, 3m/6m SAAR, real/nominal | K26: EUA | L26: Verificado
A27: US-022 | B27: Inflação | C27: Expectativas | D27: 5y5y Forward Inflation Expectation | E27: FRED | F27: T5YIFR | G27: Diária | H27: % | I27: Taxa | J27: Nível, Δ p.p. (MoM, YoY, 3/6/12m) | K27: EUA | L27: Verificado | M27: Substitui o FRA 5Y5Y SOFR
A28: US-023 | B28: Inflação | C28: Expectativas | D28: FRA 5Y5Y SOFR / inflation swaps | E28: Bloomberg | F28: — | G28: Diária | H28: % | I28: Taxa | J28: Nível, Δ p.p. (MoM, YoY, 3/6/12m) | K28: v2 | L28: Pago | M28: Usar T5YIFR
A29: US-024 | B29: Inflação | C29: Expectativas | D29: Michigan 1y inflation expectations | E29: FRED | F29: MICH | G29: Mensal | H29: % | I29: Taxa | J29: Nível, Δ p.p. (MoM, YoY, 3/6/12m) | K29: EUA | L29: Verificado | M29: Adicionado
A30: US-025 | B30: Inflação | C30: Antecedentes | D30: Manheim Used Vehicle Value Index | E30: Cox Automotive | F30: Download (site) | G30: Mensal | H30: Índice | I30: Índice | J30: Nível, MoM, QoQ, YoY, acum. 3/6/9/12m, 3m/6m SAAR, real/nominal | K30: v2 | L30: Sem API
A31: US-026 | B31: Inflação | C31: Antecedentes | D31: Container freight (Drewry / Freightos) | E31: Drewry / Freightos | F31: — | G31: Semanal | H31: US$/FEU | I31: Índice | J31: Nível, MoM, QoQ, YoY, acum. 3/6/9/12m, 3m/6m SAAR, real/nominal | K31: v2 | L31: Pago
A32: US-027 | B32: Atividade | C32: PIB | D32: Real GDP (nível, QoQ SAAR) | E32: FRED (BEA) | F32: GDPC1 / A191RL1Q225SBEA | G32: Trimestral | H32: US$ bi 2017 | I32: Índice | J32: Nível, MoM, QoQ, YoY, acum. 3/6/9/12m, 3m/6m SAAR, real/nominal | K32: EUA | L32: Verificado
A33: US-028 | B33: Atividade | C33: PIB | D33: Real GDP change (US$ tri) × Unemployment | E33: Argus | F33: Δ GDPC1 × UNRATE | G33: Trimestral | H33: US$ tri | I33: Derivado | J33: Conforme definição da fórmula | K33: EUA | L33: Derivado
A34: US-029 | B34: Atividade | C34: PIB | D34: GDP goods × services | E34: BEA API | F34: NIPA T10206 | G34: Trimestral | H34: US$ bi | I34: Índice | J34: Nível, MoM, QoQ, YoY, acum. 3/6/9/12m, 3m/6m SAAR, real/nominal | K34: v2 | L34: Confirmar
A35: US-030 | B35: Atividade | C35: PIB | D35: GDPNow | E35: FRED (Atlanta Fed) | F35: GDPNOW | G35: Contínua | H35: % SAAR | I35: Taxa | J35: Nível, Δ p.p. (MoM, YoY, 3/6/12m) | K35: EUA | L35: Verificado | M35: 3,7% para 3T26 na verificação
A36: US-031 | B36: Atividade | C36: Consumo | D36: Retail Sales (nominal e real) | E36: FRED (Census) | F36: RSAFS / RRSFS | G36: Mensal | H36: US$ mi | I36: Fluxo | J36: Nível, soma 3/12m, MoM % (SA), YoY %, real/nominal, % PIB | K36: EUA | L36: Verificado
A37: US-032 | B37: Atividade | C37: Consumo | D37: Real PCE e Private Consumption YoY | E37: FRED (BEA) | F37: PCEC96 | G37: Mensal | H37: US$ bi | I37: Fluxo | J37: Nível, soma 3/12m, MoM % (SA), YoY %, real/nominal, % PIB | K37: EUA | L37: Verificado
A38: US-033 | B38: Atividade | C38: Vendas | D38: Wholesale Sales | E38: FRED (Census) | F38: A mapear | G38: Mensal | H38: US$ mi | I38: Fluxo | J38: Nível, soma 3/12m, MoM % (SA), YoY %, real/nominal, % PIB | K38: v2 | L38: A mapear
A39: US-034 | B39: Atividade | C39: Vendas | D39: Selected Services Revenue | E39: Census QSS | F39: API Census | G39: Trimestral | H39: US$ mi | I39: Fluxo | J39: Nível, soma 3/12m, MoM % (SA), YoY %, real/nominal, % PIB | K39: v2 | L39: Confirmar
A40: US-035 | B40: Atividade | C40: Estoques | D40: Change in Private Inventories | E40: FRED (BEA) | F40: CBIC1 | G40: Trimestral | H40: US$ bi | I40: Fluxo | J40: Nível, soma 3/12m, MoM % (SA), YoY %, real/nominal, % PIB | K40: EUA | L40: Verificado
A41: US-036 | B41: Atividade | C41: Estoques | D41: Manufacturers Inventories/Sales | E41: FRED (Census) | F41: MNFCTRIRSA | G41: Mensal | H41: x | I41: Taxa | J41: Nível, Δ p.p. (MoM, YoY, 3/6/12m) | K41: EUA | L41: Verificado | M41: Proxy para excess inventory
A42: US-037 | B42: Atividade | C42: Indústria | D42: Industrial Production | E42: FRED (Fed) | F42: INDPRO | G42: Mensal | H42: Índice | I42: Índice | J42: Nível, MoM, QoQ, YoY, acum. 3/6/9/12m, 3m/6m SAAR, real/nominal | K42: EUA | L42: Verificado | M42: Adicionado
...

Sheet Central
A1: Aba Central — Command Center e notícias
A2: O que aparece na primeira tela e de onde vem.
A5: Bloco | B5: Componente | C5: Conteúdo | D5: Fonte | E5: Fase | F5: Observação
A6: Faixa de mercado | B6: Ticker no topo | C6: Ibovespa, USD/BRL, S&P 500, UST 10Y, Broad Dollar, Brent, ouro, VIX | D6: FMP + FRED + BCB SGS | E6: MVP | F6: Atualização diária; intraday só com plano pago
A7: Regime | B7: Cartões Brasil | C7: Selic × neutro implícito, IPCA 12m × meta, desocupação, Focus IPCA/Selic | D7: Abas Brasil (derivados) | E7: MVP | F7: Cada cartão leva à aba de origem
A8: Regime | B8: Cartões EUA | C8: Fed funds, Core PCE, desemprego, curva 10y-2y, GDPNow | D8: Aba EUA | E8: EUA
A9: Agenda | B9: Próximos 7 dias | C9: Divulgações do IBGE, BCB, BLS/BEA; reuniões de Copom e FOMC | D9: IBGE API de calendário + FRED releases + curado | E9: MVP | F9: Calendário de Copom/FOMC curado manualmente
A10: Última divulgação | B10: O que saiu | C10: Último dado × anterior × Focus (quando houver) | D10: Derivado | E10: MVP | F10: Consenso para os EUA não tem fonte gratuita
A11: Notícias | B11: Feed oficial | C11: Comunicados e notas de BCB, Fed, Tesouro, IBGE (Agência de Notícias) | D11: RSS oficiais | E11: MVP | F11: Fonte primária, zero risco jurídico
A12: Notícias | B12: Feed de imprensa | C12: Manchetes de veículos selecionados (título + link) | D12: RSS de veículos + Google News RSS por consulta | E12: MVP | F12: Só título, fonte e link; marcação por país/tema via palavra-chave
A13: Notícias | B13: Eventos globais | C13: Volume de notícias por país/tema (geopolítica) | D13: GDELT DOC API | E13: v2
A14: Notícias | B14: Resumo do dia | C14: Síntese automática das notícias por tema | D14: Claude API (modelo leve) | E14: v2 | F14: Custo de API: alguns US$/mês
A15: Monitor | B15: Saúde dos dados | C15: Fontes com falha ou atrasadas | D15: Tabela ingestion_runs | E15: MVP
A16: Monitor | B16: Teses | C16: Teses ativas e gatilhos próximos de disparar | D16: Aba Teses | E16: v2
A17: Monitor | B17: Alertas | C17: Alertas disparados nas últimas 24h | D17: Motor de alertas | E17: v3

Sheet Fontes
A1: Registro de fontes
A2: Cada fonte vira um adapter isolado no pipeline.
A5: Fonte | B5: Acesso | C5: Autenticação | D5: Limite / observação | E5: Risco técnico | F5: Custo
A6: BCB SGS | B6: REST JSON/CSV (api.bcb.gov.br) | C6: Nenhuma | D6: Séries diárias: máx. 10 anos por consulta (fatiar janela) | E6: Médio | F6: Grátis
A7: BCB Olinda — Focus | B7: OData REST | C7: Nenhuma | D7: Filtros OData obrigatórios para volume grande | E7: Médio | F7: Grátis
A8: BCB Portal de Dados Abertos | B8: Site / CKAN | C8: Nenhuma | D8: Limita requisições em rajada (429 observado) | E8: Médio | F8: Grátis
A9: IBGE SIDRA | B9: REST (apisidra.ibge.gov.br) | C9: Nenhuma | D9: Sintaxe verbosa; tabelas mudam de número em revisões de base | E9: Médio | F9: Grátis
A10: IBGE API de calendário | B10: REST (servicodados.ibge.gov.br) | C10: Nenhuma | D10: Agenda de divulgações | E10: Baixo | F10: Grátis
A11: ComexStat (MDIC) | B11: REST | C11: Nenhuma | D11: Consultas por NCM, país, período | E11: Médio | F11: Grátis
A12: Tesouro Transparente | B12: API Séries Temporais (RTN, JSON) · CKAN / xlsx | C12: Nenhuma | D12: RTN por API JSON paginada (decisão 0010); RMD ainda em planilha | E12: Baixo | F12: Grátis
A13: Ipeadata | B13: OData REST | C13: Nenhuma | D13: Agrega séries de terceiros; conferir atualização | E13: Médio | F13: Grátis
A14: Câmara / Senado Dados Abertos | B14: REST | C14: Nenhuma | D14: — | E14: Baixo | F14: Grátis
A15: TSE Dados Abertos | B15: CSV | C15: Nenhuma | D15: Arquivos grandes por eleição | E15: Baixo | F15: Grátis
A16: ANBIMA / B3 | B16: Arquivos diários no site | C16: Nenhuma (API ANBIMA é paga) | D16: Formatos mudam sem aviso | E16: Alto | F16: Grátis / pago
... A25: BCB site (API Copom) | B25: JSON (www.bcb.gov.br/api/servico/sitebcb) | C25: Nenhuma | D25: Não documentada; comunicados e atas do Copom | E25: Médio | F25: Grátis
